<?xml version="1.0" ?>
<!-- =================================================================================== -->
<!-- |    This document was autogenerated by xacro from jenga_robot.urdf.xacro         | -->
<!-- |    EDITING THIS FILE BY HAND IS NOT RECOMMENDED                                 | -->
<!-- =================================================================================== -->
<robot name="jenga_robot" xmlns:xacro="http://ros.org/wiki/xacro">
  <gazebo>
    <plugin filename="libgazebo_ros_control.so" name="ros_control"/>
    <plugin filename="libroboticsgroup_gazebo_mimic_joint_plugin.so" name="mimic_joint">
      <joint>gripper_joint</joint>
      <mimicJoint>gripper_prismatic_joint_2</mimicJoint>
    </plugin>
  </gazebo>
  <transmission name="turntable_transmission">
    <type>transmission_interface/SimpleTransmission</type>
    <joint name="turntable_joint">
      <hardwareInterface>hardware_interface/PositionJointInterface</hardwareInterface>
    </joint>
    <actuator name="turntable_motor">
      <hardwareInterface>EffortJointInterface</hardwareInterface>
      <mechanicalReduction>1</mechanicalReduction>
    </actuator>
  </transmission>
  <!--link name="plate_top_link"/-->
  <!--joint name="fixed" type="fixed">
      <parent link="plate_top_link" />
      <child link="ph_base_link" />
   </joint-->
  <transmission name="tran1">
    <type>transmission_interface/SimpleTransmission</type>
    <joint name="joint_1">
      <hardwareInterface>hardware_interface/PositionJointInterface</hardwareInterface>
    </joint>
    <actuator name="motor1">
      <hardwareInterface>EffortJointInterface</hardwareInterface>
      <mechanicalReduction>1</mechanicalReduction>
    </actuator>
  </transmission>
  <transmission name="tran2">
    <type>transmission_interface/SimpleTransmission</type>
    <joint name="joint_2">
      <hardwareInterface>hardware_interface/PositionJointInterface</hardwareInterface>
    </joint>
    <actuator name="motor2">
      <hardwareInterface>EffortJointInterface</hardwareInterface>
      <mechanicalReduction>1</mechanicalReduction>
    </actuator>
  </transmission>
  <transmission name="tran3">
    <type>transmission_interface/SimpleTransmission</type>
    <joint name="joint_3">
      <hardwareInterface>hardware_interface/PositionJointInterface</hardwareInterface>
    </joint>
    <actuator name="motor3">
      <hardwareInterface>EffortJointInterface</hardwareInterface>
      <mechanicalReduction>1</mechanicalReduction>
    </actuator>
  </transmission>
  <transmission name="tran4">
    <type>transmission_interface/SimpleTransmission</type>
    <joint name="joint_4">
      <hardwareInterface>hardware_interface/PositionJointInterface</hardwareInterface>
    </joint>
    <actuator name="motor4">
      <hardwareInterface>EffortJointInterface</hardwareInterface>
      <mechanicalReduction>1</mechanicalReduction>
    </actuator>
  </transmission>
  <transmission name="tran5">
    <type>transmission_interface/SimpleTransmission</type>
    <joint name="joint_5">
      <hardwareInterface>hardware_interface/PositionJointInterface</hardwareInterface>
    </joint>
    <actuator name="motor5">
      <hardwareInterface>EffortJointInterface</hardwareInterface>
      <mechanicalReduction>1</mechanicalReduction>
    </actuator>
  </transmission>
  <transmission name="tran6">
    <type>transmission_interface/SimpleTransmission</type>
    <joint name="gripper_joint">
      <hardwareInterface>hardware_interface/PositionJointInterface</hardwareInterface>
    </joint>
    <actuator name="motor6">
      <hardwareInterface>EffortJointInterface</hardwareInterface>
      <mechanicalReduction>1</mechanicalReduction>
    </actuator>
  </transmission>
  <!--        <xacro:include filename="$(find jenga_robot_description)/urdf/hopper.urdf.xacro"/> -->
  <link name="world"/>
  <!-- links -->
  <link name="frame_main_link">
    <visual>
      <origin rpy="0 -1.570795 0" xyz="0.3048 -1.3589 0"/>
      <geometry>
        <mesh filename="package://jenga_robot_description/meshes/frame.stl" scale="0.0254 0.0254 0.0254"/>
      </geometry>
      <material name="">
        <color rgba="0.15 0.15 0.15 1.0"/>
      </material>
    </visual>
    <collision>
      <origin rpy="0 -1.570795 0" xyz="0.3048 -1.3589 0"/>
      <geometry>
        <mesh filename="package://jenga_robot_description/meshes/frame.stl" scale="0.0254 0.0254 0.0254"/>
      </geometry>
    </collision>
    <inertial>
      <origin rpy="0 0 0" xyz="0 0 0"/>
      <mass value="1"/>
      <inertia ixx="1.0" ixy="0.0" ixz="0.0" iyy="1.0" iyz="0.0" izz="1.0"/>
    </inertial>
  </link>
  <link name="frame_top_link">
    <inertial>
      <origin rpy="0 0 0" xyz="0 0 0"/>
      <mass value="1"/>
      <inertia ixx="1.0" ixy="0.0" ixz="0.0" iyy="1.0" iyz="0.0" izz="1.0"/>
    </inertial>
  </link>
  <!-- joints -->
  <joint name="frame_base_joint" type="fixed">
    <origin rpy="0.0 0.0 0.0" xyz="0.0 0.0 0.00635"/>
    <parent link="world"/>
    <child link="frame_main_link"/>
  </joint>
  <joint name="frame_turntable_joint" type="fixed">
    <origin rpy="0 0 0" xyz="0 0 0.8636"/>
    <parent link="frame_main_link"/>
    <child link="frame_top_link"/>
  </joint>
  <gazebo reference="frame_main_link">
    <collision>
      <surface>
        <bounce>
          <threshold>100000</threshold>
        </bounce>
        <friction>
          <ode>
            <mu>10000000</mu>
            <mu2>10000000</mu2>
            <slip1>0.0</slip1>
            <slip2>0.0</slip2>
          </ode>
          <bullet>
            <friction>10000000</friction>
            <friction2>10000000</friction2>
          </bullet>
        </friction>
        <contact>
          <ode>
            <kd>100</kd>
          </ode>
          <bullet>
            <kp>1000000000</kp>
            <kd>100</kd>
            <soft_erp>0.20</soft_erp>
          </bullet>
        </contact>
      </surface>
    </collision>
    <selfCollide>true</selfCollide>
  </gazebo>
  <!-- links -->
  <link name="turntable_main_link">
    <visual>
      <origin rpy="0 0 0" xyz="0 0 0"/>
      <geometry>
        <cylinder length="0.03175" radius="0.2286"/>
      </geometry>
      <material name="">
        <color rgba="0.34 0.35 0.36 1.0"/>
      </material>
    </visual>
    <collision>
      <origin rpy="0 0 0" xyz="0 0 0"/>
      <geometry>
        <cylinder length="0.03175" radius="0.2286"/>
      </geometry>
    </collision>
    <inertial>
      <origin rpy="0 0 0" xyz="0 0 0"/>
      <mass value="2"/>
      <inertia ixx="0.0262969904" ixy="0.0" ixz="0.0" iyy="0.0262969904" iyz="0.0" izz="0.05225796"/>
    </inertial>
  </link>
  <link name="arm_mount_link">
    <inertial>
      <origin rpy="0 0 0" xyz="0 0 0"/>
      <mass value="1"/>
      <inertia ixx="1.0" ixy="0.0" ixz="0.0" iyy="1.0" iyz="0.0" izz="1.0"/>
    </inertial>
  </link>
  <!-- joints -->
  <joint name="turntable_joint" type="revolute">
    <origin rpy="0.0 0.0 0.0" xyz="0.0 0.0 0.0"/>
    <parent link="frame_top_link"/>
    <child link="turntable_main_link"/>
    <axis xyz="0 0 1"/>
    <limit effort="6" lower="-3.14159" upper="3.14159" velocity="1.571"/>
  </joint>
  <joint name="arm_mount_joint" type="fixed">
    <origin rpy="0 3.14159 0" xyz="0.1143 0 -0.079375"/>
    <parent link="turntable_main_link"/>
    <child link="arm_mount_link"/>
  </joint>
  <!-- links -->
  <link name="arm_base_link">
    <visual>
      <origin rpy="0 0 0" xyz="0 0 0"/>
      <geometry>
        <mesh filename="package://widowx_arm_description/meshes/base_link.stl"/>
      </geometry>
      <material name="">
        <color rgba="0.15 0.15 0.15 1.0"/>
      </material>
    </visual>
    <collision>
      <origin rpy="0 0 0" xyz="0 0 0"/>
      <geometry>
        <mesh filename="package://widowx_arm_description/meshes/base_link.stl"/>
      </geometry>
    </collision>
    <inertial>
      <origin rpy="0 0 0" xyz="0 0 0"/>
      <mass value="0.75"/>
      <inertia ixx="0.00219844" ixy="0.0" ixz="0.0" iyy="0.00219844" iyz="0.0" izz="0.00338438"/>
    </inertial>
  </link>
  <link name="shoulder_link">
    <visual>
      <origin rpy="0 0 0" xyz="0 0 0"/>
      <geometry>
        <mesh filename="package://widowx_arm_description/meshes/shoulder_link.stl"/>
      </geometry>
      <material name="">
        <color rgba="0.15 0.15 0.15 1.0"/>
      </material>
    </visual>
    <collision>
      <origin rpy="0 0 0" xyz="0 0 0"/>
      <geometry>
        <mesh filename="package://widowx_arm_description/meshes/shoulder_link.stl"/>
      </geometry>
    </collision>
    <inertial>
      <origin rpy="0 0 0" xyz="0 0 0"/>
      <mass value="0.08"/>
      <inertia ixx="0.00007227" ixy="0.0" ixz="0.0" iyy="0.00007227" iyz="0.0" izz="0.00012321"/>
    </inertial>
  </link>
  <link name="biceps_link">
    <visual>
      <origin rpy="0 0 0" xyz="0 0 0"/>
      <geometry>
        <mesh filename="package://widowx_arm_description/meshes/biceps_link.new.stl"/>
      </geometry>
      <material name="">
        <color rgba="0.15 0.15 0.15 1.0"/>
      </material>
    </visual>
    <collision>
      <origin rpy="0 0 0" xyz="0 0 0"/>
      <geometry>
        <mesh filename="package://widowx_arm_description/meshes/biceps_link.new.stl"/>
      </geometry>
    </collision>
    <inertial>
      <origin rpy="0 0 0" xyz="0 0 0"/>
      <mass value="0.270"/>
      <inertia ixx="0.00091125" ixy="0.0" ixz="0.0" iyy="0.00078525" iyz="0.0" izz="0.00023850"/>
    </inertial>
  </link>
  <link name="forearm_link">
    <visual>
      <origin rpy="0 0 0" xyz="0 0 0"/>
      <geometry>
        <mesh filename="package://widowx_arm_description/meshes/forearm_link.new.stl"/>
      </geometry>
      <material name="">
        <color rgba="0.15 0.15 0.15 1.0"/>
      </material>
    </visual>
    <collision>
      <origin rpy="0 0 0" xyz="0 0 0"/>
      <geometry>
        <mesh filename="package://widowx_arm_description/meshes/forearm_link.new.stl"/>
      </geometry>
    </collision>
    <inertial>
      <origin rpy="0 0 0" xyz="0 0 0"/>
      <mass value="0.130"/>
      <inertia ixx="0.00030442" ixy="0.0" ixz="0.0" iyy="0.00029467" iyz="0.0" izz="0.00004442"/>
    </inertial>
  </link>
  <link name="wrist_1_link">
    <visual>
      <origin rpy="0 0 0" xyz="0 0 0"/>
      <geometry>
        <mesh filename="package://widowx_arm_description/meshes/wrist_1_link.stl"/>
      </geometry>
      <material name="">
        <color rgba="0.15 0.15 0.15 1.0"/>
      </material>
    </visual>
    <collision>
      <origin rpy="0 0 0" xyz="0 0 0"/>
      <geometry>
        <mesh filename="package://widowx_arm_description/meshes/wrist_1_link.stl"/>
      </geometry>
    </collision>
    <inertial>
      <origin rpy="0 0 0" xyz="0 0 0"/>
      <mass value="0.085"/>
      <inertia ixx="0.00006304" ixy="0.0" ixz="0.0" iyy="0.00005667" iyz="0.0" izz="0.00002904"/>
    </inertial>
  </link>
  <link name="wrist_2_link">
    <visual>
      <origin rpy="0 0 0" xyz="0 0 0"/>
      <geometry>
        <mesh filename="package://widowx_arm_description/meshes/wrist_2_link.new.stl"/>
      </geometry>
      <material name="">
        <color rgba="0.15 0.15 0.15 1.0"/>
      </material>
    </visual>
    <collision>
      <origin rpy="0 0 0" xyz="0 0 0"/>
      <geometry>
        <mesh filename="package://widowx_arm_description/meshes/wrist_2_link.new.stl"/>
      </geometry>
    </collision>
    <inertial>
      <origin rpy="0 0 0" xyz="0 0 0"/>
      <mass value="0.065"/>
      <inertia ixx="0.00002708" ixy="0.0" ixz="0.0" iyy="0.00001842" iyz="0.0" izz="0.00001842"/>
    </inertial>
  </link>
  <!--link name="${prefix}gripper_rail_link">
         <visual>
            <origin xyz="0 0 0" rpy="0 0 1.57" />
            <geometry>
               <mesh filename="package://widowx_arm_description/meshes/gripper_rail_link.stl"/>
            </geometry>
            <xacro:material_black />
         </visual>
         <collision>
            <origin xyz="0 0 0" rpy="0 0 0" />
            <geometry>
               <mesh filename="package://widowx_arm_description/meshes/gripper_rail_link.stl"/>
            </geometry>
         </collision>
         <inertial>
            <origin xyz="0 0 0" rpy="0 0 0" />
            <mass value="1" />
            <inertia ixx="1.0" ixy="0.0" ixz="0.0" iyy="1.0" iyz="0.0" izz="1.0" />
         </inertial>
      </link-->
  <!--link name="${prefix}gripper_aux_link">
      </link-->
  <!--link name="${prefix}gripper_1_link">
         <visual>
            <origin xyz="0 -0.0007 0" rpy="0 0 1.57" />
            <geometry>
               <mesh filename="package://widowx_arm_description/meshes/gripper_hand_fixed_link.stl"/>
            </geometry>
            <xacro:material_black />
         </visual>
         <collision>
            <origin xyz="0 0 0" rpy="0 0 0" />
            <geometry>
               <mesh filename="package://widowx_arm_description/meshes/gripper_hand_fixed_link.stl"/>
            </geometry>
         </collision>
         <inertial>
            <origin xyz="0 0 0" rpy="0 0 0" />
            <mass value="1" />
            <inertia ixx="1.0" ixy="0.0" ixz="0.0" iyy="1.0" iyz="0.0" izz="1.0" />
         </inertial>
      </link>
      <link name="${prefix}gripper_2_link">
         <visual>
            <origin xyz="0 0.0007 0" rpy="0 0 -1.57" />
            <geometry>
               <mesh filename="package://widowx_arm_description/meshes/gripper_hand_fixed_link.stl"/>
            </geometry>
            <xacro:material_black />
         </visual>
         <collision>
            <origin xyz="0 0 0" rpy="0 0 0" />
            <geometry>
               <mesh filename="package://widowx_arm_description/meshes/gripper_hand_fixed_link.stl"/>
            </geometry>
         </collision>
         <inertial>
            <origin xyz="0 0 0" rpy="0 0 0" />
            <mass value="1" />
            <inertia ixx="1.0" ixy="0.0" ixz="0.0" iyy="1.0" iyz="0.0" izz="1.0" />
         </inertial>
      </link-->
  <!-- joints -->
  <joint name="arm_base_joint" type="fixed">
    <origin rpy="0.0 0.0 0.0" xyz="0.0 0.0 0.0"/>
    <parent link="arm_mount_link"/>
    <child link="arm_base_link"/>
  </joint>
  <joint name="joint_1" type="revolute">
    <origin rpy="0 0 0" xyz="0 0 0.125"/>
    <parent link="arm_base_link"/>
    <child link="shoulder_link"/>
    <axis xyz="0 0 1"/>
    <limit effort="6" lower="-2.617" upper="2.617" velocity="0.785"/>
  </joint>
  <joint name="joint_2" type="revolute">
    <!--origin xyz="0.04825 0 0.14203" rpy="0 0 0" /-->
    <origin rpy="0 0 0" xyz="0 0 0"/>
    <parent link="shoulder_link"/>
    <child link="biceps_link"/>
    <axis xyz="0 1 0"/>
    <limit effort="6" lower="-1.689" upper="1.689" velocity="1.571"/>
  </joint>
  <joint name="joint_3" type="revolute">
    <origin rpy="0 1.570795 0" xyz="0.04825 0 0.14203"/>
    <parent link="biceps_link"/>
    <child link="forearm_link"/>
    <axis xyz="0 1 0"/>
    <limit effort="6" lower="-2.83" upper="1.658" velocity="1.571"/>
  </joint>
  <joint name="joint_4" type="revolute">
    <origin rpy="0 0 0" xyz="0 0 0.14203"/>
    <parent link="forearm_link"/>
    <child link="wrist_1_link"/>
    <axis xyz="0 1 0"/>
    <limit effort="6" lower="-1.875" upper="1.973" velocity="1.571"/>
  </joint>
  <joint name="joint_5" type="revolute">
    <origin rpy="0 0 0" xyz="0 0 0.0715"/>
    <parent link="wrist_1_link"/>
    <child link="wrist_2_link"/>
    <axis xyz="0 0 1"/>
    <limit effort="6" lower="-2.617" upper="2.617" velocity="1.571"/>
  </joint>
  <!--joint name="${prefix}joint_6" type="fixed">
         <origin xyz = "0 0 ${M_SCALE*43}" rpy="0 0 0" />
         <parent link="${prefix}wrist_2_link" />
         <child link="${prefix}gripper_rail_link" />
         <axis xyz="0 0 1" />
         <limit lower="-0.31" upper="0.1" effort="6" velocity="0.5" />
      </joint-->
  <!--joint name="${prefix}gripper_revolute_joint" type="revolute">
         <origin xyz = "0 0 0.065" rpy="0 0 0" />
         <parent link="${prefix}wrist_2_link" />
         <child link="${prefix}gripper_aux_link" />
         <axis xyz="0 0 1" />
         <limit lower="-2.6" upper="2.6" effort="6" velocity="0.5" />
      </joint-->
  <!--joint name="${prefix}gripper_prismatic_joint_1" type="prismatic">
         <origin xyz="0 0 0" rpy="0 0 0" />
         <parent link="${prefix}gripper_rail_link" />
         <child link="${prefix}gripper_1_link" />
         <axis xyz="0 -1 0" />
         <limit lower="0" upper="0.027" effort="6" velocity="0.5" />
      </joint>
      <joint name="${prefix}gripper_prismatic_joint_2" type="prismatic">
         <origin xyz="0 0 0" rpy="0 0 0" />
         <parent link="${prefix}gripper_rail_link" />
         <child link="${prefix}gripper_2_link" />
         <mimic joint="${prefix}gripper_prismatic_joint_1" />
         <axis xyz="0 1 0" />
         <limit lower="0" upper="0.027" effort="6" velocity="0.5" />
      </joint-->
  <link name="gripper_rail_link">
    <visual>
      <origin rpy="0 0 1.57" xyz="0 0 0"/>
      <geometry>
        <mesh filename="package://widowx_arm_description/meshes/gripper_rail_link.stl"/>
      </geometry>
      <material name="">
        <color rgba="0.15 0.15 0.15 1.0"/>
      </material>
    </visual>
    <collision>
      <origin rpy="0 0 1.57" xyz="0 0 0"/>
      <geometry>
        <mesh filename="package://widowx_arm_description/meshes/gripper_rail_link.stl"/>
      </geometry>
    </collision>
    <inertial>
      <origin rpy="0 0 0" xyz="0 0 0"/>
      <mass value="0.01"/>
      <inertia ixx="0.00000417" ixy="0.0" ixz="0.0" iyy="0.00000142" iyz="0.0" izz="0.00000542"/>
    </inertial>
  </link>
  <!--link name="${prefix}gripper_aux_link">
   </link-->
  <link name="gripper_1_link">
    <visual>
      <origin rpy="0 0 1.57" xyz="0 -0.0007 0"/>
      <geometry>
        <mesh filename="package://widowx_arm_description/meshes/gripper_hand_fixed_link.stl"/>
      </geometry>
      <material name="">
        <color rgba="0.15 0.15 0.15 1.0"/>
      </material>
    </visual>
    <collision>
      <origin rpy="0 0 1.57" xyz="0 -0.0007 0"/>
      <geometry>
        <mesh filename="package://widowx_arm_description/meshes/gripper_hand_fixed_link.stl"/>
      </geometry>
    </collision>
    <inertial>
      <origin rpy="0 0 0" xyz="0 0 0"/>
      <mass value="0.005"/>
      <inertia ixx="0.00000083" ixy="0.0" ixz="0.0" iyy="0.00000133" iyz="0.0" izz="0.00000083"/>
    </inertial>
  </link>
  <link name="gripper_2_link">
    <visual>
      <origin rpy="0 0 -1.57" xyz="0 0.0007 0"/>
      <geometry>
        <mesh filename="package://widowx_arm_description/meshes/gripper_hand_fixed_link.stl"/>
      </geometry>
      <material name="">
        <color rgba="0.15 0.15 0.15 1.0"/>
      </material>
    </visual>
    <collision>
      <origin rpy="0 0 -1.57" xyz="0 0.0007 0"/>
      <geometry>
        <mesh filename="package://widowx_arm_description/meshes/gripper_hand_fixed_link.stl"/>
      </geometry>
    </collision>
    <inertial>
      <origin rpy="0 0 0" xyz="0 0 0"/>
      <mass value="0.005"/>
      <inertia ixx="0.00000083" ixy="0.0" ixz="0.0" iyy="0.00000133" iyz="0.0" izz="0.00000083"/>
    </inertial>
  </link>
  <joint name="joint_6" type="fixed">
    <origin rpy="0 0 0" xyz="0 0 0.043"/>
    <parent link="wrist_2_link"/>
    <child link="gripper_rail_link"/>
    <axis xyz="0 0 1"/>
  </joint>
  <joint name="gripper_joint" type="prismatic">
    <origin rpy="0 0 0" xyz="0 0 0"/>
    <parent link="gripper_rail_link"/>
    <child link="gripper_1_link"/>
    <axis xyz="0 -1 0"/>
    <limit effort="0" lower="0.001" upper="0.0158" velocity="0.5"/>
  </joint>
  <joint name="gripper_prismatic_joint_2" type="prismatic">
    <origin rpy="0 0 0" xyz="0 0 0"/>
    <parent link="gripper_rail_link"/>
    <child link="gripper_2_link"/>
    <mimic joint="gripper_joint"/>
    <axis xyz="0 1 0"/>
    <limit effort="0" lower="0.001" upper="0.0158" velocity="0.5"/>
  </joint>
  <gazebo reference="gripper_1_link">
    <collision>
      <surface>
        <bounce>
          <threshold>100000</threshold>
        </bounce>
        <friction>
          <ode>
            <mu>10000000</mu>
            <mu2>10000000</mu2>
            <slip1>0.0</slip1>
            <slip2>0.0</slip2>
          </ode>
          <bullet>
            <friction>10000000</friction>
            <friction2>10000000</friction2>
          </bullet>
        </friction>
        <contact>
          <ode>
            <kd>100</kd>
          </ode>
          <bullet>
            <kp>1000000000</kp>
            <kd>100</kd>
            <soft_erp>0.20</soft_erp>
          </bullet>
        </contact>
      </surface>
    </collision>
  </gazebo>
  <gazebo reference="gripper_2_link">
    <collision>
      <surface>
        <bounce>
          <threshold>100000</threshold>
        </bounce>
        <friction>
          <ode>
            <mu>10000000</mu>
            <mu2>10000000</mu2>
            <slip1>0.0</slip1>
            <slip2>0.0</slip2>
          </ode>
          <bullet>
            <friction>10000000</friction>
            <friction2>10000000</friction2>
          </bullet>
        </friction>
        <contact>
          <ode>
            <kd>100</kd>
          </ode>
          <bullet>
            <kp>1000000000</kp>
            <kd>100</kd>
            <soft_erp>0.20</soft_erp>
          </bullet>
        </contact>
      </surface>
    </collision>
  </gazebo>
  <!--link name="gripper_link"/>
    <joint name="gripper_link_joint" type="revolute">
      <origin xyz="0 0 0.110" rpy="0 0 0"/>
      <parent link="${prefix}wrist_1_link" />
      <child link="gripper_link"/>
      <limit effort="6" velocity="1" lower="-3.14" upper="3.14"/>
      <axis xyz="1 0 0"/>
    </joint-->
  <!-- links -->
  <link name="build_platform_main_link">
    <visual>
      <origin rpy="0 0 0" xyz="0 0 0"/>
      <geometry>
        <box size="0.6096 0.5334 0.00254"/>
      </geometry>
      <material name="">
        <color rgba="0.15 0.15 0.15 1.0"/>
      </material>
    </visual>
    <collision>
      <origin rpy="0 0 0" xyz="0 0 0"/>
      <geometry>
        <box size="0.6096 0.5334 0.00254"/>
      </geometry>
    </collision>
    <inertial>
      <origin rpy="0 0 0" xyz="0 0 0"/>
      <mass value="1"/>
      <inertia ixx="1.0" ixy="0.0" ixz="0.0" iyy="1.0" iyz="0.0" izz="1.0"/>
    </inertial>
  </link>
  <!-- joints -->
  <joint name="build_platform_joint" type="fixed">
    <origin rpy="0.0 0.0 0.0" xyz="0.0 0.0 0.28448"/>
    <parent link="frame_main_link"/>
    <child link="build_platform_main_link"/>
  </joint>
  <gazebo reference="build_platform_main_link">
    <selfCollide>true</selfCollide>
    <collision>
      <surface>
        <bounce>
          <threshold>100000</threshold>
        </bounce>
        <friction>
          <ode>
            <mu>10000000</mu>
            <mu2>10000000</mu2>
            <slip1>0.0</slip1>
            <slip2>0.0</slip2>
          </ode>
          <bullet>
            <friction>10000000</friction>
            <friction2>10000000</friction2>
          </bullet>
        </friction>
        <contact>
          <ode>
            <kd>100</kd>
          </ode>
          <bullet>
            <kp>1000000000</kp>
            <kd>100</kd>
            <soft_erp>0.20</soft_erp>
          </bullet>
        </contact>
      </surface>
    </collision>
  </gazebo>
</robot>
